<?xml version="1.0"?>
<robot name="pi_robot">
    <link name="torso_link">
        <visual>
            <origin xyz="0 0 0.12" rpy="0 0 0"/>
            <geometry>
                <cylinder radius="0.05" length="0.24"/>
            </geometry>
            <material name="Yellow2">
                <color rgba="0.8 0.8 0 1.0"/>
            </material>
       </visual>
    </link>

        <link name="left_shoulder_link">
        <visual>
            <origin xyz="0 0 0" rpy="0 0 0"/>
            <geometry>
                <box size="0.025 0.015 0.05"/>
            </geometry>
            <material name="Green1">
                <color rgba="0 1 0 1.0"/>
            </material>
       </visual>
    </link>

    
    <link name="left_shoulder_forward_link">
        <visual>
            <origin xyz="0 0 0" rpy="0 0 0"/>
            <geometry>
                <box size="0.03 0.05 0.03"/>
            </geometry>
            <material name="Blue1">
                <color rgba="0 0 0.9 1.0"/>
            </material>
       </visual>
    </link>

    <link name="left_shoulder_up_link">
        <visual>
            <origin xyz="0 0 0" rpy="0 0 0"/>
            <geometry>
                <box size="0.03 0.05 0.03"/>
            </geometry>
            <material name="Blue2">
                <color rgba="0 0 0.7 1.0"/>
            </material>
       </visual>
    </link>
    

    
    <link name="left_upper_arm_link">
        <visual>
            <origin xyz="0 0 0" rpy="0 0 0"/>
            <geometry>
                <cylinder radius="0.0075" length="0.05"/>
            </geometry>
            <material name="Grey1">
                <color rgba="0.9 0.9 0.9 1.0"/>
            </material>
       </visual>
    </link>

    <link name="left_elbow_link">
        <visual>
            <origin xyz="0 0 0" rpy="0 0 0"/>
            <geometry>
                <box size="0.035 0.035 0.05"/>
            </geometry>
            <material name="Blue2">
                <color rgba="0 0 0.7 1.0"/>
            </material>
       </visual>
    </link>
    

    
    <link name="left_lower_arm_link">
        <visual>
            <origin xyz="0 0 0" rpy="0 0 0"/>
            <geometry>
                <cylinder radius="0.0075" length="0.11"/>
            </geometry>
            <material name="Grey1">
                <color rgba="0.9 0.9 0.9 1.0"/>
            </material>
       </visual>
    </link>
    

    <link name="left_wrist_link">
        <visual>
            <origin xyz="0 0 0" rpy="1.57 0 0"/>
            <geometry>
                <box size="0.03 0.05 0.03"/>
            </geometry>
            <material name="Blue2">
                <color rgba="0 0 0.7 1.0"/>
            </material>
       </visual>
    </link>
    

    <link name="left_hand_link">
        <visual>
            <origin xyz="0 0 0" rpy="0 0 0"/>
            <geometry>
                <box size="0.03 0.01 0.06"/>
            </geometry>
            <material name="Grey1">
                <color rgba="0.7 0.7 0.7 1.0"/>
            </material>
       </visual>
    </link>
    


 	<joint name="left_shoulder_joint" type="fixed">
    	<parent link="torso_link"/>
    	<child link="left_shoulder_link"/>
    	<origin xyz="0 0.055 0.165" rpy="0 0 0"/>
	</joint>
	

	
 	<joint name="left_shoulder_forward_joint" type="revolute">
    	<parent link="left_shoulder_link"/>
    	<child link="left_shoulder_forward_link"/>
    	<origin xyz="0 0.025 0" rpy="0 0 0"/>
       	<limit lower="-1.57" upper="1.57" effort="10" velocity="3"/>
        <axis xyz="0 0 1"/>
	</joint>
	

	
 	<joint name="left_shoulder_up_joint" type="revolute">
    	<parent link="left_shoulder_forward_link"/>
    	<child link="left_shoulder_up_link"/>
    	<origin xyz="0 0.04 -0.01" rpy="0 -0.707 0"/>
       	<limit lower="-1.57" upper="1.57" effort="10" velocity="3"/>
        <axis xyz="0 1 0"/>
	</joint>
	

	
 	<joint name="left_upper_arm_joint" type="fixed">
    	<parent link="left_shoulder_up_link"/>
    	<child link="left_upper_arm_link"/>
    	<origin xyz="0 0 -0.05" rpy="0 0 0"/>
	</joint>
	
 
 	<joint name="left_elbow_joint" type="revolute">
    	<parent link="left_upper_arm_link"/>
    	<child link="left_elbow_link"/>
    	<origin xyz="-0.005 0 -0.05" rpy="0 0 0"/>
       	<limit lower="-3.146" upper="3.146" effort="10" velocity="3"/>
        <axis xyz="0 0 1"/>
	</joint>
	

	
 	<joint name="left_lower_arm_joint" type="fixed">
    	<parent link="left_elbow_link"/>
    	<child link="left_lower_arm_link"/>
    	<origin xyz="0 0 -0.08" rpy="0 0 0"/>
	</joint>
	

	
 	<joint name="left_wrist_joint" type="revolute">
    	<parent link="left_lower_arm_link"/>
    	<child link="left_wrist_link"/>
    	<origin xyz="0 0 -0.05" rpy="0 0 0"/>
       	<limit lower="-1.57" upper="1.57" effort="10" velocity="3"/>
        <axis xyz="1 0 0"/>
	</joint>

	
 	<joint name="left_hand_joint" type="fixed">
    	<parent link="left_wrist_link"/>
    	<child link="left_hand_link"/>
    	<origin xyz="0 0 -0.055" rpy="0 0 0"/>
	</joint>

</robot>