<?xml version="1.0" encoding="UTF-8"?>
<robot name="template">


<!-- //////////////////////// Link and Joints //////////////////////// -->
<link name="base">
	<visual>
		<geometry>
			<box size="2 2 0.1" />
		</geometry>
		<origin rpy="0 0 0" xyz="0 0 -0.05" />
	</visual>
	<collision>
		<geometry>
			<box size="2 2 0.1" />
		</geometry>
		<origin rpy="0 0 0" xyz="0 0 -0.05" />
	</collision>
</link>

<link name="cylinder_4">
	<visual>
		<geometry>
			<cylinder radius="0.05" length=".3" />
		</geometry>
		<material name="white"/>
		<origin rpy="0 0 0" xyz="0 0 0" />
	</visual>
	<collision>
		<geometry>
			<cylinder radius="0.05" length=".3" />
		</geometry>
		<origin rpy="0 0 0" xyz="0 0 0" />
	</collision>
</link>

<link name="cylinder_4_arm">
	<visual>
		<geometry>
			<box size="0.03 0.03 0.2"/>
		</geometry>
		<origin rpy="0 0 0" xyz="0 0 0" />
	</visual>
	<collision>
		<geometry>
			<box size="0.03 0.03 0.2"/>
		</geometry>
		<origin rpy="0 0 0" xyz="0 0 0" />
	</collision>
</link>

<joint name="base_cylinder_4" type="revolute">
	<axis xyz="0 0 1"/>
	<parent link="base"/>
	<child link="cylinder_4" />
  	<origin xyz="0 0 0"/>
  	<limit lower="-1.57" upper="1.57" effort="10" velocity="3"/>
</joint>

<joint name="cylinder_4_with_arm" type="fixed">
	<parent link="cylinder_4"/>
	<child link="cylinder_4_arm" />
  	<origin xyz="0 0 .15"/>
  	<limit lower="-1.57" upper="1.57" effort="10" velocity="3"/>
</joint>


<link name="cylinder_5">
	<visual>
		<geometry>
			<cylinder radius="0.05" length=".3" />
		</geometry>
		<material name="white"/>
		<origin rpy="1.57 0 0" xyz="0 0 0" />
	</visual>
	<collision>
		<geometry>
			<cylinder radius="0.05" length=".3" />
		</geometry>
		<origin rpy="1.57 0 0" xyz="0 0 0" />
	</collision>
</link>


<link name="cylinder_5_arm">
	<visual>
		<geometry>
			<box size="0.03 0.03 0.2"/>
		</geometry>
		<origin rpy="1.57 0 0" xyz="0 0 0" />
	</visual>
	<collision>
		<geometry>
			<box size="0.03 0.03 0.2"/>
		</geometry>
		<origin rpy="1.57 0 0" xyz="0 0 0" />
	</collision>
</link>

<joint name="cylinder_4arm_cylinder_5" type="revolute">
	<axis xyz="0 1 0"/>
	<parent link="cylinder_4_arm"/>
	<child link="cylinder_5" />
  	<origin xyz="0 0 .15"/>
  	<limit lower="-1.57" upper="1.57" effort="10" velocity="3"/>
</joint>

<joint name="cylinder_5_with_arm" type="fixed">
	<parent link="cylinder_5"/>
	<child link="cylinder_5_arm" />
  	<origin xyz="0 .15 0"/>
  	<limit lower="-1.57" upper="1.57" effort="10" velocity="3"/>
</joint>


<link name="box_6">
	<visual>
		<geometry>
			<box size=".1 .1 .1" />
		</geometry>
		<material name="white"/>
		<origin rpy="0 0 0" xyz="0 0 0" />
	</visual>
	<collision>
		<geometry>
			<box size=".1 .1 .1" />
		</geometry>
		<origin rpy="0 0 0" xyz="0 0 0" />
	</collision>
</link>


<link name="box_6_arm">
	<visual>
		<geometry>
			<box size="0.03 0.03 0.3"/>
		</geometry>
		<origin rpy="0 0 0" xyz="0 0 0" />
	</visual>
	<collision>
		<geometry>
			<box size="0.03 0.03 0.3"/>
		</geometry>
		<origin rpy="0 0 0" xyz="0 0 0" />
	</collision>
</link>

<joint name="cylinder_5arm_box3" type="prismatic">
	<axis xyz="0 0 1"/>
	<parent link="cylinder_5_arm"/>
	<child link="box_6" />
  	<origin xyz="0 .15 0"/>
  	<limit lower="-1.57" upper="1.57" effort="10" velocity="3"/>
</joint>

<joint name="box_6_with_arm" type="fixed">
	<parent link="box_6"/>
	<child link="box_6_arm" />
  	<origin xyz="0 0 .15"/>
  	<limit lower="-1.57" upper="1.57" effort="10" velocity="3"/>
</joint>


<link name="end_efffector">
	<visual>
		<geometry>
			<box size=".1 .1 .1" />
		</geometry>
		<material name="white"/>
		<origin rpy="0 0 0" xyz="0 0 0" />
	</visual>
	<collision>
		<geometry>
			<box size=".1 .1 .1" />
		</geometry>
		<origin rpy="0 0 0" xyz="0 0 0" />
	</collision>
</link>

<joint name="box_6_arm_end_effector" type="fixed">
	<parent link="box_6_arm"/>
	<child link="end_efffector" />
  	<origin xyz="0 0 .15"/>
  	<limit lower="-1.57" upper="1.57" effort="10" velocity="3"/>
</joint>

<!-- Material -->
<material name="white">
    <color rgba="1 1 1 1"/>
</material>
<material name="blue">
    <color rgba="0 0 0.9 1.0"/>
</material>

<!-- //////////////////////// END ////////////////////////-->

</robot>