<?xml version="1.0"?>
<robot name="2link">

  <material name="blue">
    <color rgba="0 0 0.8 1"/>
  </material>

  <material name="white">
    <color rgba="1 1 1 1"/>
  </material>

    <material name="black">
    <color rgba="0 0 0 1"/>
  </material>

<link name="base">
	<visual>
		<geometry>
			<box size="0.1 0.1 0.1"/>
		</geometry>
	</visual>	
</link>

<link name="arm_1">
	<visual>
		<origin rpy="0 0 0" xyz="0 0 0"/>
		<geometry>
			<box size=".05 .05 .6"/>
		</geometry>
		<material name="white"/>
	</visual>	
</link>

<link name="joint_1_2">
	<visual>
		<origin rpy="0 0 0" xyz="0 0 0"/>
		<geometry>
			<box size="0.1 0.1 0.1"/>
		</geometry>
		<material name="black"/>
	</visual>	
</link>

<link name="arm_2">
	<visual>
		<origin rpy="0 0 0" xyz="0 0 0"/>
		<geometry>
			<box size=".05 .05 .6"/>
		</geometry>
		<material name="blue"/>
	</visual>	
</link>

	<joint name="base_1" type="revolute">
    	<parent link="base"/>
    	<child link="arm_1"/>
    	<origin xyz="0 0 0.3" rpy="0 0 0"/>
    	<axis xyz="0 0 1"/>
    	<limit lower="-3.1416" upper="3.1416" effort="10" velocity="3"/>
	</joint>

	<joint name="1_joint" type="revolute">
    	<parent link="arm_1"/>
    	<child link="joint_1_2"/>
    	<origin xyz="0 0 0.3" rpy="0 0 0"/>
    	<axis xyz="1 0 0"/>
    	<limit lower="-3.1416" upper="3.1416" effort="10" velocity="3"/>
	</joint>

	<joint name="joint_2" type="revolute">
    	<parent link="joint_1_2"/>
    	<child link="arm_2"/>
    	<origin xyz="0 0 0.3" rpy="0 0 0"/>
    	<limit lower="-1.57" upper="1.57" effort="10" velocity="3"/>
        <axis xyz="0 0 1"/>
	</joint>
</robot>